Workbook

Sheet Dashboard
A1: DASHBOARD COMPANY FOLLOW-UP & PROGRESS REPORT
A2: Data Terkonsolidasi Berdasarkan Project ID Terakhir (Lengkap dengan Dropdown & Note Otomatis)
A3: 📌 FORMAT RUKUN NOTE PROGRESS: [Jenis & Qty Unit] _ [Lama Masa Sewa] _ [Catatan Status Terbaru] (Contoh: Forklift 3 Ton (2 Unit) _ 2 Tahun _ SPH dikirim ke User)
B5: TOTAL PERUSAHAAN UNIK | D5: ACTIVE PROSPECTS | E5: ACTIVE LEADS | F5: DEAL / WON | G5: ALERT: OVERDUE / IDLE | H5: ALERT: WARNING (3-14 DAYS)
B6: =COUNTA(Company_Latest!D2:D1000) | D6: =COUNTIF(Company_Latest!H2:H1000, "Prospect") | E6: =COUNTIF(Company_Latest!H2:H1000, "Leads") | F6: =COUNTIF(Company_Latest!H2:H1000, "Deal / Won") | G6: =COUNTIF(Company_Latest!L2:L1000, "OVERDUE (IDLE)") | H6: =COUNTIF(Company_Latest!L2:L1000, "WARNING (3-14 Days)")
A8: DAFTAR TINDAKAN PRIORITAS (ACTION ALERT LIST - OTOMATIS BERDASARKAN CONSOLIDATED NOTE)
A9: No | B9: Sales Officer | C9: Company ID | D9: Company Name | E9: Project ID Terakhir | F9: Last Progress | G9: Detail Progress & Note ([Unit] _ [Masa Sewa] _ [Catatan]) | H9: Status Alert
A10: =IF(B10<>"", 1, "") | B10: =IFERROR(INDEX(Company_Latest!C$2:C$500, SMALL(IF((Company_Latest!$L$2:$L$500="OVERDUE (IDLE)")+(Company_Latest!$L$2:$L$500="WARNING (3-14 Days)"), ROW(Company_Latest!$L$2:$L$500)-1), 1)), "") | C10: =IFERROR(INDEX(Company_Latest!D$2:D$500, SMALL(IF((Company_Latest!$L$2:$L$500="OVERDUE (IDLE)")+(Company_Latest!$L$2:$L$500="WARNING (3-14 Days)"), ROW(Company_Latest!$L$2:$L$500)-1), 1)), "") | D10: =IFERROR(INDEX(Company_Latest!E$2:E$500, SMALL(IF((Company_Latest!$L$2:$L$500="OVERDUE (IDLE)")+(Company_Latest!$L$2:$L$500="WARNING (3-14 Days)"), ROW(Company_Latest!$L$2:$L$500)-1), 1)), "") | E10: =IFERROR(INDEX(Company_Latest!G$2:G$500, SMALL(IF((Company_Latest!$L$2:$L$500="OVERDUE (IDLE)")+(Company_Latest!$L$2:$L$500="WARNING (3-14 Days)"), ROW(Company_Latest!$L$2:$L$500)-1), 1)), "") | F10: =IFERROR(INDEX(Company_Latest!H$2:H$500, SMALL(IF((Company_Latest!$L$2:$L$500="OVERDUE (IDLE)")+(Company_Latest!$L$2:$L$500="WARNING (3-14 Days)"), ROW(Company_Latest!$L$2:$L$500)-1), 1)), "") | G10: =IFERROR(INDEX(Company_Latest!K$2:K$500, SMALL(IF((Company_Latest!$L$2:$L$500="OVERDUE (IDLE)")+(Company_Latest!$L$2:$L$500="WARNING (3-14 Days)"), ROW(Company_Latest!$L$2:$L$500)-1), 1)), "") | H10: =IFERROR(INDEX(Company_Latest!L$2:L$500, SMALL(IF((Company_Latest!$L$2:$L$500="OVERDUE (IDLE)")+(Company_Latest!$L$2:$L$500="WARNING (3-14 Days)"), ROW(Company_Latest!$L$2:$L$500)-1), 1)), "")
A11: =IF(B11<>"", 2, "") | B11: =IFERROR(INDEX(Company_Latest!C$2:C$500, SMALL(IF((Company_Latest!$L$2:$L$500="OVERDUE (IDLE)")+(Company_Latest!$L$2:$L$500="WARNING (3-14 Days)"), ROW(Company_Latest!$L$2:$L$500)-1), 2)), "") | C11: =IFERROR(INDEX(Company_Latest!D$2:D$500, SMALL(IF((Company_Latest!$L$2:$L$500="OVERDUE (IDLE)")+(Company_Latest!$L$2:$L$500="WARNING (3-14 Days)"), ROW(Company_Latest!$L$2:$L$500)-1), 2)), "") | D11: =IFERROR(INDEX(Company_Latest!E$2:E$500, SMALL(IF((Company_Latest!$L$2:$L$500="OVERDUE (IDLE)")+(Company_Latest!$L$2:$L$500="WARNING (3-14 Days)"), ROW(Company_Latest!$L$2:$L$500)-1), 2)), "") | E11: =IFERROR(INDEX(Company_Latest!G$2:G$500, SMALL(IF((Company_Latest!$L$2:$L$500="OVERDUE (IDLE)")+(Company_Latest!$L$2:$L$500="WARNING (3-14 Days)"), ROW(Company_Latest!$L$2:$L$500)-1), 2)), "") | F11: =IFERROR(INDEX(Company_Latest!H$2:H$500, SMALL(IF((Company_Latest!$L$2:$L$500="OVERDUE (IDLE)")+(Company_Latest!$L$2:$L$500="WARNING (3-14 Days)"), ROW(Company_Latest!$L$2:$L$500)-1), 2)), "") | G11: =IFERROR(INDEX(Company_Latest!K$2:K$500, SMALL(IF((Company_Latest!$L$2:$L$500="OVERDUE (IDLE)")+(Company_Latest!$L$2:$L$500="WARNING (3-14 Days)"), ROW(Company_Latest!$L$2:$L$500)-1), 2)), "") | H11: =IFERROR(INDEX(Company_Latest!L$2:L$500, SMALL(IF((Company_Latest!$L$2:$L$500="OVERDUE (IDLE)")+(Company_Latest!$L$2:$L$500="WARNING (3-14 Days)"), ROW(Company_Latest!$L$2:$L$500)-1), 2)), "")
A12: =IF(B12<>"", 3, "") | B12: =IFERROR(INDEX(Company_Latest!C$2:C$500, SMALL(IF((Company_Latest!$L$2:$L$500="OVERDUE (IDLE)")+(Company_Latest!$L$2:$L$500="WARNING (3-14 Days)"), ROW(Company_Latest!$L$2:$L$500)-1), 3)), "") | C12: =IFERROR(INDEX(Company_Latest!D$2:D$500, SMALL(IF((Company_Latest!$L$2:$L$500="OVERDUE (IDLE)")+(Company_Latest!$L$2:$L$500="WARNING (3-14 Days)"), ROW(Company_Latest!$L$2:$L$500)-1), 3)), "") | D12: =IFERROR(INDEX(Company_Latest!E$2:E$500, SMALL(IF((Company_Latest!$L$2:$L$500="OVERDUE (IDLE)")+(Company_Latest!$L$2:$L$500="WARNING (3-14 Days)"), ROW(Company_Latest!$L$2:$L$500)-1), 3)), "") | E12: =IFERROR(INDEX(Company_Latest!G$2:G$500, SMALL(IF((Company_Latest!$L$2:$L$500="OVERDUE (IDLE)")+(Company_Latest!$L$2:$L$500="WARNING (3-14 Days)"), ROW(Company_Latest!$L$2:$L$500)-1), 3)), "") | F12: =IFERROR(INDEX(Company_Latest!H$2:H$500, SMALL(IF((Company_Latest!$L$2:$L$500="OVERDUE (IDLE)")+(Company_Latest!$L$2:$L$500="WARNING (3-14 Days)"), ROW(Company_Latest!$L$2:$L$500)-1), 3)), "") | G12: =IFERROR(INDEX(Company_Latest!K$2:K$500, SMALL(IF((Company_Latest!$L$2:$L$500="OVERDUE (IDLE)")+(Company_Latest!$L$2:$L$500="WARNING (3-14 Days)"), ROW(Company_Latest!$L$2:$L$500)-1), 3)), "") | H12: =IFERROR(INDEX(Company_Latest!L$2:L$500, SMALL(IF((Company_Latest!$L$2:$L$500="OVERDUE (IDLE)")+(Company_Latest!$L$2:$L$500="WARNING (3-14 Days)"), ROW(Company_Latest!$L$2:$L$500)-1), 3)), "")
A13: =IF(B13<>"", 4, "") | B13: =IFERROR(INDEX(Company_Latest!C$2:C$500, SMALL(IF((Company_Latest!$L$2:$L$500="OVERDUE (IDLE)")+(Company_Latest!$L$2:$L$500="WARNING (3-14 Days)"), ROW(Company_Latest!$L$2:$L$500)-1), 4)), "") | C13: =IFERROR(INDEX(Company_Latest!D$2:D$500, SMALL(IF((Company_Latest!$L$2:$L$500="OVERDUE (IDLE)")+(Company_Latest!$L$2:$L$500="WARNING (3-14 Days)"), ROW(Company_Latest!$L$2:$L$500)-1), 4)), "") | D13: =IFERROR(INDEX(Company_Latest!E$2:E$500, SMALL(IF((Company_Latest!$L$2:$L$500="OVERDUE (IDLE)")+(Company_Latest!$L$2:$L$500="WARNING (3-14 Days)"), ROW(Company_Latest!$L$2:$L$500)-1), 4)), "") | E13: =IFERROR(INDEX(Company_Latest!G$2:G$500, SMALL(IF((Company_Latest!$L$2:$L$500="OVERDUE (IDLE)")+(Company_Latest!$L$2:$L$500="WARNING (3-14 Days)"), ROW(Company_Latest!$L$2:$L$500)-1), 4)), "") | F13: =IFERROR(INDEX(Company_Latest!H$2:H$500, SMALL(IF((Company_Latest!$L$2:$L$500="OVERDUE (IDLE)")+(Company_Latest!$L$2:$L$500="WARNING (3-14 Days)"), ROW(Company_Latest!$L$2:$L$500)-1), 4)), "") | G13: =IFERROR(INDEX(Company_Latest!K$2:K$500, SMALL(IF((Company_Latest!$L$2:$L$500="OVERDUE (IDLE)")+(Company_Latest!$L$2:$L$500="WARNING (3-14 Days)"), ROW(Company_Latest!$L$2:$L$500)-1), 4)), "") | H13: =IFERROR(INDEX(Company_Latest!L$2:L$500, SMALL(IF((Company_Latest!$L$2:$L$500="OVERDUE (IDLE)")+(Company_Latest!$L$2:$L$500="WARNING (3-14 Days)"), ROW(Company_Latest!$L$2:$L$500)-1), 4)), "")
A14: =IF(B14<>"", 5, "") | B14: =IFERROR(INDEX(Company_Latest!C$2:C$500, SMALL(IF((Company_Latest!$L$2:$L$500="OVERDUE (IDLE)")+(Company_Latest!$L$2:$L$500="WARNING (3-14 Days)"), ROW(Company_Latest!$L$2:$L$500)-1), 5)), "") | C14: =IFERROR(INDEX(Company_Latest!D$2:D$500, SMALL(IF((Company_Latest!$L$2:$L$500="OVERDUE (IDLE)")+(Company_Latest!$L$2:$L$500="WARNING (3-14 Days)"), ROW(Company_Latest!$L$2:$L$500)-1), 5)), "") | D14: =IFERROR(INDEX(Company_Latest!E$2:E$500, SMALL(IF((Company_Latest!$L$2:$L$500="OVERDUE (IDLE)")+(Company_Latest!$L$2:$L$500="WARNING (3-14 Days)"), ROW(Company_Latest!$L$2:$L$500)-1), 5)), "") | E14: =IFERROR(INDEX(Company_Latest!G$2:G$500, SMALL(IF((Company_Latest!$L$2:$L$500="OVERDUE (IDLE)")+(Company_Latest!$L$2:$L$500="WARNING (3-14 Days)"), ROW(Company_Latest!$L$2:$L$500)-1), 5)), "") | F14: =IFERROR(INDEX(Company_Latest!H$2:H$500, SMALL(IF((Company_Latest!$L$2:$L$500="OVERDUE (IDLE)")+(Company_Latest!$L$2:$L$500="WARNING (3-14 Days)"), ROW(Company_Latest!$L$2:$L$500)-1), 5)), "") | G14: =IFERROR(INDEX(Company_Latest!K$2:K$500, SMALL(IF((Company_Latest!$L$2:$L$500="OVERDUE (IDLE)")+(Company_Latest!$L$2:$L$500="WARNING (3-14 Days)"), ROW(Company_Latest!$L$2:$L$500)-1), 5)), "") | H14: =IFERROR(INDEX(Company_Latest!L$2:L$500, SMALL(IF((Company_Latest!$L$2:$L$500="OVERDUE (IDLE)")+(Company_Latest!$L$2:$L$500="WARNING (3-14 Days)"), ROW(Company_Latest!$L$2:$L$500)-1), 5)), "")
A15: =IF(B15<>"", 6, "") | B15: =IFERROR(INDEX(Company_Latest!C$2:C$500, SMALL(IF((Company_Latest!$L$2:$L$500="OVERDUE (IDLE)")+(Company_Latest!$L$2:$L$500="WARNING (3-14 Days)"), ROW(Company_Latest!$L$2:$L$500)-1), 6)), "") | C15: =IFERROR(INDEX(Company_Latest!D$2:D$500, SMALL(IF((Company_Latest!$L$2:$L$500="OVERDUE (IDLE)")+(Company_Latest!$L$2:$L$500="WARNING (3-14 Days)"), ROW(Company_Latest!$L$2:$L$500)-1), 6)), "") | D15: =IFERROR(INDEX(Company_Latest!E$2:E$500, SMALL(IF((Company_Latest!$L$2:$L$500="OVERDUE (IDLE)")+(Company_Latest!$L$2:$L$500="WARNING (3-14 Days)"), ROW(Company_Latest!$L$2:$L$500)-1), 6)), "") | E15: =IFERROR(INDEX(Company_Latest!G$2:G$500, SMALL(IF((Company_Latest!$L$2:$L$500="OVERDUE (IDLE)")+(Company_Latest!$L$2:$L$500="WARNING (3-14 Days)"), ROW(Company_Latest!$L$2:$L$500)-1), 6)), "") | F15: =IFERROR(INDEX(Company_Latest!H$2:H$500, SMALL(IF((Company_Latest!$L$2:$L$500="OVERDUE (IDLE)")+(Company_Latest!$L$2:$L$500="WARNING (3-14 Days)"), ROW(Company_Latest!$L$2:$L$500)-1), 6)), "") | G15: =IFERROR(INDEX(Company_Latest!K$2:K$500, SMALL(IF((Company_Latest!$L$2:$L$500="OVERDUE (IDLE)")+(Company_Latest!$L$2:$L$500="WARNING (3-14 Days)"), ROW(Company_Latest!$L$2:$L$500)-1), 6)), "") | H15: =IFERROR(INDEX(Company_Latest!L$2:L$500, SMALL(IF((Company_Latest!$L$2:$L$500="OVERDUE (IDLE)")+(Company_Latest!$L$2:$L$500="WARNING (3-14 Days)"), ROW(Company_Latest!$L$2:$L$500)-1), 6)), "")
A16: =IF(B16<>"", 7, "") | B16: =IFERROR(INDEX(Company_Latest!C$2:C$500, SMALL(IF((Company_Latest!$L$2:$L$500="OVERDUE (IDLE)")+(Company_Latest!$L$2:$L$500="WARNING (3-14 Days)"), ROW(Company_Latest!$L$2:$L$500)-1), 7)), "") | C16: =IFERROR(INDEX(Company_Latest!D$2:D$500, SMALL(IF((Company_Latest!$L$2:$L$500="OVERDUE (IDLE)")+(Company_Latest!$L$2:$L$500="WARNING (3-14 Days)"), ROW(Company_Latest!$L$2:$L$500)-1), 7)), "") | D16: =IFERROR(INDEX(Company_Latest!E$2:E$500, SMALL(IF((Company_Latest!$L$2:$L$500="OVERDUE (IDLE)")+(Company_Latest!$L$2:$L$500="WARNING (3-14 Days)"), ROW(Company_Latest!$L$2:$L$500)-1), 7)), "") | E16: =IFERROR(INDEX(Company_Latest!G$2:G$500, SMALL(IF((Company_Latest!$L$2:$L$500="OVERDUE (IDLE)")+(Company_Latest!$L$2:$L$500="WARNING (3-14 Days)"), ROW(Company_Latest!$L$2:$L$500)-1), 7)), "") | F16: =IFERROR(INDEX(Company_Latest!H$2:H$500, SMALL(IF((Company_Latest!$L$2:$L$500="OVERDUE (IDLE)")+(Company_Latest!$L$2:$L$500="WARNING (3-14 Days)"), ROW(Company_Latest!$L$2:$L$500)-1), 7)), "") | G16: =IFERROR(INDEX(Company_Latest!K$2:K$500, SMALL(IF((Company_Latest!$L$2:$L$500="OVERDUE (IDLE)")+(Company_Latest!$L$2:$L$500="WARNING (3-14 Days)"), ROW(Company_Latest!$L$2:$L$500)-1), 7)), "") | H16: =IFERROR(INDEX(Company_Latest!L$2:L$500, SMALL(IF((Company_Latest!$L$2:$L$500="OVERDUE (IDLE)")+(Company_Latest!$L$2:$L$500="WARNING (3-14 Days)"), ROW(Company_Latest!$L$2:$L$500)-1), 7)), "")
A17: =IF(B17<>"", 8, "") | B17: =IFERROR(INDEX(Company_Latest!C$2:C$500, SMALL(IF((Company_Latest!$L$2:$L$500="OVERDUE (IDLE)")+(Company_Latest!$L$2:$L$500="WARNING (3-14 Days)"), ROW(Company_Latest!$L$2:$L$500)-1), 8)), "") | C17: =IFERROR(INDEX(Company_Latest!D$2:D$500, SMALL(IF((Company_Latest!$L$2:$L$500="OVERDUE (IDLE)")+(Company_Latest!$L$2:$L$500="WARNING (3-14 Days)"), ROW(Company_Latest!$L$2:$L$500)-1), 8)), "") | D17: =IFERROR(INDEX(Company_Latest!E$2:E$500, SMALL(IF((Company_Latest!$L$2:$L$500="OVERDUE (IDLE)")+(Company_Latest!$L$2:$L$500="WARNING (3-14 Days)"), ROW(Company_Latest!$L$2:$L$500)-1), 8)), "") | E17: =IFERROR(INDEX(Company_Latest!G$2:G$500, SMALL(IF((Company_Latest!$L$2:$L$500="OVERDUE (IDLE)")+(Company_Latest!$L$2:$L$500="WARNING (3-14 Days)"), ROW(Company_Latest!$L$2:$L$500)-1), 8)), "") | F17: =IFERROR(INDEX(Company_Latest!H$2:H$500, SMALL(IF((Company_Latest!$L$2:$L$500="OVERDUE (IDLE)")+(Company_Latest!$L$2:$L$500="WARNING (3-14 Days)"), ROW(Company_Latest!$L$2:$L$500)-1), 8)), "") | G17: =IFERROR(INDEX(Company_Latest!K$2:K$500, SMALL(IF((Company_Latest!$L$2:$L$500="OVERDUE (IDLE)")+(Company_Latest!$L$2:$L$500="WARNING (3-14 Days)"), ROW(Company_Latest!$L$2:$L$500)-1), 8)), "") | H17: =IFERROR(INDEX(Company_Latest!L$2:L$500, SMALL(IF((Company_Latest!$L$2:$L$500="OVERDUE (IDLE)")+(Company_Latest!$L$2:$L$500="WARNING (3-14 Days)"), ROW(Company_Latest!$L$2:$L$500)-1), 8)), "")
A18: =IF(B18<>"", 9, "") | B18: =IFERROR(INDEX(Company_Latest!C$2:C$500, SMALL(IF((Company_Latest!$L$2:$L$500="OVERDUE (IDLE)")+(Company_Latest!$L$2:$L$500="WARNING (3-14 Days)"), ROW(Company_Latest!$L$2:$L$500)-1), 9)), "") | C18: =IFERROR(INDEX(Company_Latest!D$2:D$500, SMALL(IF((Company_Latest!$L$2:$L$500="OVERDUE (IDLE)")+(Company_Latest!$L$2:$L$500="WARNING (3-14 Days)"), ROW(Company_Latest!$L$2:$L$500)-1), 9)), "") | D18: =IFERROR(INDEX(Company_Latest!E$2:E$500, SMALL(IF((Company_Latest!$L$2:$L$500="OVERDUE (IDLE)")+(Company_Latest!$L$2:$L$500="WARNING (3-14 Days)"), ROW(Company_Latest!$L$2:$L$500)-1), 9)), "") | E18: =IFERROR(INDEX(Company_Latest!G$2:G$500, SMALL(IF((Company_Latest!$L$2:$L$500="OVERDUE (IDLE)")+(Company_Latest!$L$2:$L$500="WARNING (3-14 Days)"), ROW(Company_Latest!$L$2:$L$500)-1), 9)), "") | F18: =IFERROR(INDEX(Company_Latest!H$2:H$500, SMALL(IF((Company_Latest!$L$2:$L$500="OVERDUE (IDLE)")+(Company_Latest!$L$2:$L$500="WARNING (3-14 Days)"), ROW(Company_Latest!$L$2:$L$500)-1), 9)), "") | G18: =IFERROR(INDEX(Company_Latest!K$2:K$500, SMALL(IF((Company_Latest!$L$2:$L$500="OVERDUE (IDLE)")+(Company_Latest!$L$2:$L$500="WARNING (3-14 Days)"), ROW(Company_Latest!$L$2:$L$500)-1), 9)), "") | H18: =IFERROR(INDEX(Company_Latest!L$2:L$500, SMALL(IF((Company_Latest!$L$2:$L$500="OVERDUE (IDLE)")+(Company_Latest!$L$2:$L$500="WARNING (3-14 Days)"), ROW(Company_Latest!$L$2:$L$500)-1), 9)), "")
A19: =IF(B19<>"", 10, "") | B19: =IFERROR(INDEX(Company_Latest!C$2:C$500, SMALL(IF((Company_Latest!$L$2:$L$500="OVERDUE (IDLE)")+(Company_Latest!$L$2:$L$500="WARNING (3-14 Days)"), ROW(Company_Latest!$L$2:$L$500)-1), 10)), "") | C19: =IFERROR(INDEX(Company_Latest!D$2:D$500, SMALL(IF((Company_Latest!$L$2:$L$500="OVERDUE (IDLE)")+(Company_Latest!$L$2:$L$500="WARNING (3-14 Days)"), ROW(Company_Latest!$L$2:$L$500)-1), 10)), "") | D19: =IFERROR(INDEX(Company_Latest!E$2:E$500, SMALL(IF((Company_Latest!$L$2:$L$500="OVERDUE (IDLE)")+(Company_Latest!$L$2:$L$500="WARNING (3-14 Days)"), ROW(Company_Latest!$L$2:$L$500)-1), 10)), "") | E19: =IFERROR(INDEX(Company_Latest!G$2:G$500, SMALL(IF((Company_Latest!$L$2:$L$500="OVERDUE (IDLE)")+(Company_Latest!$L$2:$L$500="WARNING (3-14 Days)"), ROW(Company_Latest!$L$2:$L$500)-1), 10)), "") | F19: =IFERROR(INDEX(Company_Latest!H$2:H$500, SMALL(IF((Company_Latest!$L$2:$L$500="OVERDUE (IDLE)")+(Company_Latest!$L$2:$L$500="WARNING (3-14 Days)"), ROW(Company_Latest!$L$2:$L$500)-1), 10)), "") | G19: =IFERROR(INDEX(Company_Latest!K$2:K$500, SMALL(IF((Company_Latest!$L$2:$L$500="OVERDUE (IDLE)")+(Company_Latest!$L$2:$L$500="WARNING (3-14 Days)"), ROW(Company_Latest!$L$2:$L$500)-1), 10)), "") | H19: =IFERROR(INDEX(Company_Latest!L$2:L$500, SMALL(IF((Company_Latest!$L$2:$L$500="OVERDUE (IDLE)")+(Company_Latest!$L$2:$L$500="WARNING (3-14 Days)"), ROW(Company_Latest!$L$2:$L$500)-1), 10)), "")
A20: =IF(B20<>"", 11, "") | B20: =IFERROR(INDEX(Company_Latest!C$2:C$500, SMALL(IF((Company_Latest!$L$2:$L$500="OVERDUE (IDLE)")+(Company_Latest!$L$2:$L$500="WARNING (3-14 Days)"), ROW(Company_Latest!$L$2:$L$500)-1), 11)), "") | C20: =IFERROR(INDEX(Company_Latest!D$2:D$500, SMALL(IF((Company_Latest!$L$2:$L$500="OVERDUE (IDLE)")+(Company_Latest!$L$2:$L$500="WARNING (3-14 Days)"), ROW(Company_Latest!$L$2:$L$500)-1), 11)), "") | D20: =IFERROR(INDEX(Company_Latest!E$2:E$500, SMALL(IF((Company_Latest!$L$2:$L$500="OVERDUE (IDLE)")+(Company_Latest!$L$2:$L$500="WARNING (3-14 Days)"), ROW(Company_Latest!$L$2:$L$500)-1), 11)), "") | E20: =IFERROR(INDEX(Company_Latest!G$2:G$500, SMALL(IF((Company_Latest!$L$2:$L$500="OVERDUE (IDLE)")+(Company_Latest!$L$2:$L$500="WARNING (3-14 Days)"), ROW(Company_Latest!$L$2:$L$500)-1), 11)), "") | F20: =IFERROR(INDEX(Company_Latest!H$2:H$500, SMALL(IF((Company_Latest!$L$2:$L$500="OVERDUE (IDLE)")+(Company_Latest!$L$2:$L$500="WARNING (3-14 Days)"), ROW(Company_Latest!$L$2:$L$500)-1), 11)), "") | G20: =IFERROR(INDEX(Company_Latest!K$2:K$500, SMALL(IF((Company_Latest!$L$2:$L$500="OVERDUE (IDLE)")+(Company_Latest!$L$2:$L$500="WARNING (3-14 Days)"), ROW(Company_Latest!$L$2:$L$500)-1), 11)), "") | H20: =IFERROR(INDEX(Company_Latest!L$2:L$500, SMALL(IF((Company_Latest!$L$2:$L$500="OVERDUE (IDLE)")+(Company_Latest!$L$2:$L$500="WARNING (3-14 Days)"), ROW(Company_Latest!$L$2:$L$500)-1), 11)), "")
A21: =IF(B21<>"", 12, "") | B21: =IFERROR(INDEX(Company_Latest!C$2:C$500, SMALL(IF((Company_Latest!$L$2:$L$500="OVERDUE (IDLE)")+(Company_Latest!$L$2:$L$500="WARNING (3-14 Days)"), ROW(Company_Latest!$L$2:$L$500)-1), 12)), "") | C21: =IFERROR(INDEX(Company_Latest!D$2:D$500, SMALL(IF((Company_Latest!$L$2:$L$500="OVERDUE (IDLE)")+(Company_Latest!$L$2:$L$500="WARNING (3-14 Days)"), ROW(Company_Latest!$L$2:$L$500)-1), 12)), "") | D21: =IFERROR(INDEX(Company_Latest!E$2:E$500, SMALL(IF((Company_Latest!$L$2:$L$500="OVERDUE (IDLE)")+(Company_Latest!$L$2:$L$500="WARNING (3-14 Days)"), ROW(Company_Latest!$L$2:$L$500)-1), 12)), "") | E21: =IFERROR(INDEX(Company_Latest!G$2:G$500, SMALL(IF((Company_Latest!$L$2:$L$500="OVERDUE (IDLE)")+(Company_Latest!$L$2:$L$500="WARNING (3-14 Days)"), ROW(Company_Latest!$L$2:$L$500)-1), 12)), "") | F21: =IFERROR(INDEX(Company_Latest!H$2:H$500, SMALL(IF((Company_Latest!$L$2:$L$500="OVERDUE (IDLE)")+(Company_Latest!$L$2:$L$500="WARNING (3-14 Days)"), ROW(Company_Latest!$L$2:$L$500)-1), 12)), "") | G21: =IFERROR(INDEX(Company_Latest!K$2:K$500, SMALL(IF((Company_Latest!$L$2:$L$500="OVERDUE (IDLE)")+(Company_Latest!$L$2:$L$500="WARNING (3-14 Days)"), ROW(Company_Latest!$L$2:$L$500)-1), 12)), "") | H21: =IFERROR(INDEX(Company_Latest!L$2:L$500, SMALL(IF((Company_Latest!$L$2:$L$500="OVERDUE (IDLE)")+(Company_Latest!$L$2:$L$500="WARNING (3-14 Days)"), ROW(Company_Latest!$L$2:$L$500)-1), 12)), "")
A22: =IF(B22<>"", 13, "") | B22: =IFERROR(INDEX(Company_Latest!C$2:C$500, SMALL(IF((Company_Latest!$L$2:$L$500="OVERDUE (IDLE)")+(Company_Latest!$L$2:$L$500="WARNING (3-14 Days)"), ROW(Company_Latest!$L$2:$L$500)-1), 13)), "") | C22: =IFERROR(INDEX(Company_Latest!D$2:D$500, SMALL(IF((Company_Latest!$L$2:$L$500="OVERDUE (IDLE)")+(Company_Latest!$L$2:$L$500="WARNING (3-14 Days)"), ROW(Company_Latest!$L$2:$L$500)-1), 13)), "") | D22: =IFERROR(INDEX(Company_Latest!E$2:E$500, SMALL(IF((Company_Latest!$L$2:$L$500="OVERDUE (IDLE)")+(Company_Latest!$L$2:$L$500="WARNING (3-14 Days)"), ROW(Company_Latest!$L$2:$L$500)-1), 13)), "") | E22: =IFERROR(INDEX(Company_Latest!G$2:G$500, SMALL(IF((Company_Latest!$L$2:$L$500="OVERDUE (IDLE)")+(Company_Latest!$L$2:$L$500="WARNING (3-14 Days)"), ROW(Company_Latest!$L$2:$L$500)-1), 13)), "") | F22: =IFERROR(INDEX(Company_Latest!H$2:H$500, SMALL(IF((Company_Latest!$L$2:$L$500="OVERDUE (IDLE)")+(Company_Latest!$L$2:$L$500="WARNING (3-14 Days)"), ROW(Company_Latest!$L$2:$L$500)-1), 13)), "") | G22: =IFERROR(INDEX(Company_Latest!K$2:K$500, SMALL(IF((Company_Latest!$L$2:$L$500="OVERDUE (IDLE)")+(Company_Latest!$L$2:$L$500="WARNING (3-14 Days)"), ROW(Company_Latest!$L$2:$L$500)-1), 13)), "") | H22: =IFERROR(INDEX(Company_Latest!L$2:L$500, SMALL(IF((Company_Latest!$L$2:$L$500="OVERDUE (IDLE)")+(Company_Latest!$L$2:$L$500="WARNING (3-14 Days)"), ROW(Company_Latest!$L$2:$L$500)-1), 13)), "")
A23: =IF(B23<>"", 14, "") | B23: =IFERROR(INDEX(Company_Latest!C$2:C$500, SMALL(IF((Company_Latest!$L$2:$L$500="OVERDUE (IDLE)")+(Company_Latest!$L$2:$L$500="WARNING (3-14 Days)"), ROW(Company_Latest!$L$2:$L$500)-1), 14)), "") | C23: =IFERROR(INDEX(Company_Latest!D$2:D$500, SMALL(IF((Company_Latest!$L$2:$L$500="OVERDUE (IDLE)")+(Company_Latest!$L$2:$L$500="WARNING (3-14 Days)"), ROW(Company_Latest!$L$2:$L$500)-1), 14)), "") | D23: =IFERROR(INDEX(Company_Latest!E$2:E$500, SMALL(IF((Company_Latest!$L$2:$L$500="OVERDUE (IDLE)")+(Company_Latest!$L$2:$L$500="WARNING (3-14 Days)"), ROW(Company_Latest!$L$2:$L$500)-1), 14)), "") | E23: =IFERROR(INDEX(Company_Latest!G$2:G$500, SMALL(IF((Company_Latest!$L$2:$L$500="OVERDUE (IDLE)")+(Company_Latest!$L$2:$L$500="WARNING (3-14 Days)"), ROW(Company_Latest!$L$2:$L$500)-1), 14)), "") | F23: =IFERROR(INDEX(Company_Latest!H$2:H$500, SMALL(IF((Company_Latest!$L$2:$L$500="OVERDUE (IDLE)")+(Company_Latest!$L$2:$L$500="WARNING (3-14 Days)"), ROW(Company_Latest!$L$2:$L$500)-1), 14)), "") | G23: =IFERROR(INDEX(Company_Latest!K$2:K$500, SMALL(IF((Company_Latest!$L$2:$L$500="OVERDUE (IDLE)")+(Company_Latest!$L$2:$L$500="WARNING (3-14 Days)"), ROW(Company_Latest!$L$2:$L$500)-1), 14)), "") | H23: =IFERROR(INDEX(Company_Latest!L$2:L$500, SMALL(IF((Company_Latest!$L$2:$L$500="OVERDUE (IDLE)")+(Company_Latest!$L$2:$L$500="WARNING (3-14 Days)"), ROW(Company_Latest!$L$2:$L$500)-1), 14)), "")
A24: =IF(B24<>"", 15, "") | B24: =IFERROR(INDEX(Company_Latest!C$2:C$500, SMALL(IF((Company_Latest!$L$2:$L$500="OVERDUE (IDLE)")+(Company_Latest!$L$2:$L$500="WARNING (3-14 Days)"), ROW(Company_Latest!$L$2:$L$500)-1), 15)), "") | C24: =IFERROR(INDEX(Company_Latest!D$2:D$500, SMALL(IF((Company_Latest!$L$2:$L$500="OVERDUE (IDLE)")+(Company_Latest!$L$2:$L$500="WARNING (3-14 Days)"), ROW(Company_Latest!$L$2:$L$500)-1), 15)), "") | D24: =IFERROR(INDEX(Company_Latest!E$2:E$500, SMALL(IF((Company_Latest!$L$2:$L$500="OVERDUE (IDLE)")+(Company_Latest!$L$2:$L$500="WARNING (3-14 Days)"), ROW(Company_Latest!$L$2:$L$500)-1), 15)), "") | E24: =IFERROR(INDEX(Company_Latest!G$2:G$500, SMALL(IF((Company_Latest!$L$2:$L$500="OVERDUE (IDLE)")+(Company_Latest!$L$2:$L$500="WARNING (3-14 Days)"), ROW(Company_Latest!$L$2:$L$500)-1), 15)), "") | F24: =IFERROR(INDEX(Company_Latest!H$2:H$500, SMALL(IF((Company_Latest!$L$2:$L$500="OVERDUE (IDLE)")+(Company_Latest!$L$2:$L$500="WARNING (3-14 Days)"), ROW(Company_Latest!$L$2:$L$500)-1), 15)), "") | G24: =IFERROR(INDEX(Company_Latest!K$2:K$500, SMALL(IF((Company_Latest!$L$2:$L$500="OVERDUE (IDLE)")+(Company_Latest!$L$2:$L$500="WARNING (3-14 Days)"), ROW(Company_Latest!$L$2:$L$500)-1), 15)), "") | H24: =IFERROR(INDEX(Company_Latest!L$2:L$500, SMALL(IF((Company_Latest!$L$2:$L$500="OVERDUE (IDLE)")+(Company_Latest!$L$2:$L$500="WARNING (3-14 Days)"), ROW(Company_Latest!$L$2:$L$500)-1), 15)), "")
A25: =IF(B25<>"", 16, "") | B25: =IFERROR(INDEX(Company_Latest!C$2:C$500, SMALL(IF((Company_Latest!$L$2:$L$500="OVERDUE (IDLE)")+(Company_Latest!$L$2:$L$500="WARNING (3-14 Days)"), ROW(Company_Latest!$L$2:$L$500)-1), 16)), "") | C25: =IFERROR(INDEX(Company_Latest!D$2:D$500, SMALL(IF((Company_Latest!$L$2:$L$500="OVERDUE (IDLE)")+(Company_Latest!$L$2:$L$500="WARNING (3-14 Days)"), ROW(Company_Latest!$L$2:$L$500)-1), 16)), "") | D25: =IFERROR(INDEX(Company_Latest!E$2:E$500, SMALL(IF((Company_Latest!$L$2:$L$500="OVERDUE (IDLE)")+(Company_Latest!$L$2:$L$500="WARNING (3-14 Days)"), ROW(Company_Latest!$L$2:$L$500)-1), 16)), "") | E25: =IFERROR(INDEX(Company_Latest!G$2:G$500, SMALL(IF((Company_Latest!$L$2:$L$500="OVERDUE (IDLE)")+(Company_Latest!$L$2:$L$500="WARNING (3-14 Days)"), ROW(Company_Latest!$L$2:$L$500)-1), 16)), "") | F25: =IFERROR(INDEX(Company_Latest!H$2:H$500, SMALL(IF((Company_Latest!$L$2:$L$500="OVERDUE (IDLE)")+(Company_Latest!$L$2:$L$500="WARNING (3-14 Days)"), ROW(Company_Latest!$L$2:$L$500)-1), 16)), "") | G25: =IFERROR(INDEX(Company_Latest!K$2:K$500, SMALL(IF((Company_Latest!$L$2:$L$500="OVERDUE (IDLE)")+(Company_Latest!$L$2:$L$500="WARNING (3-14 Days)"), ROW(Company_Latest!$L$2:$L$500)-1), 16)), "") | H25: =IFERROR(INDEX(Company_Latest!L$2:L$500, SMALL(IF((Company_Latest!$L$2:$L$500="OVERDUE (IDLE)")+(Company_Latest!$L$2:$L$500="WARNING (3-14 Days)"), ROW(Company_Latest!$L$2:$L$500)-1), 16)), "")
A26: =IF(B26<>"", 17, "") | B26: =IFERROR(INDEX(Company_Latest!C$2:C$500, SMALL(IF((Company_Latest!$L$2:$L$500="OVERDUE (IDLE)")+(Company_Latest!$L$2:$L$500="WARNING (3-14 Days)"), ROW(Company_Latest!$L$2:$L$500)-1), 17)), "") | C26: =IFERROR(INDEX(Company_Latest!D$2:D$500, SMALL(IF((Company_Latest!$L$2:$L$500="OVERDUE (IDLE)")+(Company_Latest!$L$2:$L$500="WARNING (3-14 Days)"), ROW(Company_Latest!$L$2:$L$500)-1), 17)), "") | D26: =IFERROR(INDEX(Company_Latest!E$2:E$500, SMALL(IF((Company_Latest!$L$2:$L$500="OVERDUE (IDLE)")+(Company_Latest!$L$2:$L$500="WARNING (3-14 Days)"), ROW(Company_Latest!$L$2:$L$500)-1), 17)), "") | E26: =IFERROR(INDEX(Company_Latest!G$2:G$500, SMALL(IF((Company_Latest!$L$2:$L$500="OVERDUE (IDLE)")+(Company_Latest!$L$2:$L$500="WARNING (3-14 Days)"), ROW(Company_Latest!$L$2:$L$500)-1), 17)), "") | F26: =IFERROR(INDEX(Company_Latest!H$2:H$500, SMALL(IF((Company_Latest!$L$2:$L$500="OVERDUE (IDLE)")+(Company_Latest!$L$2:$L$500="WARNING (3-14 Days)"), ROW(Company_Latest!$L$2:$L$500)-1), 17)), "") | G26: =IFERROR(INDEX(Company_Latest!K$2:K$500, SMALL(IF((Company_Latest!$L$2:$L$500="OVERDUE (IDLE)")+(Company_Latest!$L$2:$L$500="WARNING (3-14 Days)"), ROW(Company_Latest!$L$2:$L$500)-1), 17)), "") | H26: =IFERROR(INDEX(Company_Latest!L$2:L$500, SMALL(IF((Company_Latest!$L$2:$L$500="OVERDUE (IDLE)")+(Company_Latest!$L$2:$L$500="WARNING (3-14 Days)"), ROW(Company_Latest!$L$2:$L$500)-1), 17)), "")
A27: =IF(B27<>"", 18, "") | B27: =IFERROR(INDEX(Company_Latest!C$2:C$500, SMALL(IF((Company_Latest!$L$2:$L$500="OVERDUE (IDLE)")+(Company_Latest!$L$2:$L$500="WARNING (3-14 Days)"), ROW(Company_Latest!$L$2:$L$500)-1), 18)), "") | C27: =IFERROR(INDEX(Company_Latest!D$2:D$500, SMALL(IF((Company_Latest!$L$2:$L$500="OVERDUE (IDLE)")+(Company_Latest!$L$2:$L$500="WARNING (3-14 Days)"), ROW(Company_Latest!$L$2:$L$500)-1), 18)), "") | D27: =IFERROR(INDEX(Company_Latest!E$2:E$500, SMALL(IF((Company_Latest!$L$2:$L$500="OVERDUE (IDLE)")+(Company_Latest!$L$2:$L$500="WARNING (3-14 Days)"), ROW(Company_Latest!$L$2:$L$500)-1), 18)), "") | E27: =IFERROR(INDEX(Company_Latest!G$2:G$500, SMALL(IF((Company_Latest!$L$2:$L$500="OVERDUE (IDLE)")+(Company_Latest!$L$2:$L$500="WARNING (3-14 Days)"), ROW(Company_Latest!$L$2:$L$500)-1), 18)), "") | F27: =IFERROR(INDEX(Company_Latest!H$2:H$500, SMALL(IF((Company_Latest!$L$2:$L$500="OVERDUE (IDLE)")+(Company_Latest!$L$2:$L$500="WARNING (3-14 Days)"), ROW(Company_Latest!$L$2:$L$500)-1), 18)), "") | G27: =IFERROR(INDEX(Company_Latest!K$2:K$500, SMALL(IF((Company_Latest!$L$2:$L$500="OVERDUE (IDLE)")+(Company_Latest!$L$2:$L$500="WARNING (3-14 Days)"), ROW(Company_Latest!$L$2:$L$500)-1), 18)), "") | H27: =IFERROR(INDEX(Company_Latest!L$2:L$500, SMALL(IF((Company_Latest!$L$2:$L$500="OVERDUE (IDLE)")+(Company_Latest!$L$2:$L$500="WARNING (3-14 Days)"), ROW(Company_Latest!$L$2:$L$500)-1), 18)), "")
A28: =IF(B28<>"", 19, "") | B28: =IFERROR(INDEX(Company_Latest!C$2:C$500, SMALL(IF((Company_Latest!$L$2:$L$500="OVERDUE (IDLE)")+(Company_Latest!$L$2:$L$500="WARNING (3-14 Days)"), ROW(Company_Latest!$L$2:$L$500)-1), 19)), "") | C28: =IFERROR(INDEX(Company_Latest!D$2:D$500, SMALL(IF((Company_Latest!$L$2:$L$500="OVERDUE (IDLE)")+(Company_Latest!$L$2:$L$500="WARNING (3-14 Days)"), ROW(Company_Latest!$L$2:$L$500)-1), 19)), "") | D28: =IFERROR(INDEX(Company_Latest!E$2:E$500, SMALL(IF((Company_Latest!$L$2:$L$500="OVERDUE (IDLE)")+(Company_Latest!$L$2:$L$500="WARNING (3-14 Days)"), ROW(Company_Latest!$L$2:$L$500)-1), 19)), "") | E28: =IFERROR(INDEX(Company_Latest!G$2:G$500, SMALL(IF((Company_Latest!$L$2:$L$500="OVERDUE (IDLE)")+(Company_Latest!$L$2:$L$500="WARNING (3-14 Days)"), ROW(Company_Latest!$L$2:$L$500)-1), 19)), "") | F28: =IFERROR(INDEX(Company_Latest!H$2:H$500, SMALL(IF((Company_Latest!$L$2:$L$500="OVERDUE (IDLE)")+(Company_Latest!$L$2:$L$500="WARNING (3-14 Days)"), ROW(Company_Latest!$L$2:$L$500)-1), 19)), "") | G28: =IFERROR(INDEX(Company_Latest!K$2:K$500, SMALL(IF((Company_Latest!$L$2:$L$500="OVERDUE (IDLE)")+(Company_Latest!$L$2:$L$500="WARNING (3-14 Days)"), ROW(Company_Latest!$L$2:$L$500)-1), 19)), "") | H28: =IFERROR(INDEX(Company_Latest!L$2:L$500, SMALL(IF((Company_Latest!$L$2:$L$500="OVERDUE (IDLE)")+(Company_Latest!$L$2:$L$500="WARNING (3-14 Days)"), ROW(Company_Latest!$L$2:$L$500)-1), 19)), "")
A29: =IF(B29<>"", 20, "") | B29: =IFERROR(INDEX(Company_Latest!C$2:C$500, SMALL(IF((Company_Latest!$L$2:$L$500="OVERDUE (IDLE)")+(Company_Latest!$L$2:$L$500="WARNING (3-14 Days)"), ROW(Company_Latest!$L$2:$L$500)-1), 20)), "") | C29: =IFERROR(INDEX(Company_Latest!D$2:D$500, SMALL(IF((Company_Latest!$L$2:$L$500="OVERDUE (IDLE)")+(Company_Latest!$L$2:$L$500="WARNING (3-14 Days)"), ROW(Company_Latest!$L$2:$L$500)-1), 20)), "") | D29: =IFERROR(INDEX(Company_Latest!E$2:E$500, SMALL(IF((Company_Latest!$L$2:$L$500="OVERDUE (IDLE)")+(Company_Latest!$L$2:$L$500="WARNING (3-14 Days)"), ROW(Company_Latest!$L$2:$L$500)-1), 20)), "") | E29: =IFERROR(INDEX(Company_Latest!G$2:G$500, SMALL(IF((Company_Latest!$L$2:$L$500="OVERDUE (IDLE)")+(Company_Latest!$L$2:$L$500="WARNING (3-14 Days)"), ROW(Company_Latest!$L$2:$L$500)-1), 20)), "") | F29: =IFERROR(INDEX(Company_Latest!H$2:H$500, SMALL(IF((Company_Latest!$L$2:$L$500="OVERDUE (IDLE)")+(Company_Latest!$L$2:$L$500="WARNING (3-14 Days)"), ROW(Company_Latest!$L$2:$L$500)-1), 20)), "") | G29: =IFERROR(INDEX(Company_Latest!K$2:K$500, SMALL(IF((Company_Latest!$L$2:$L$500="OVERDUE (IDLE)")+(Company_Latest!$L$2:$L$500="WARNING (3-14 Days)"), ROW(Company_Latest!$L$2:$L$500)-1), 20)), "") | H29: =IFERROR(INDEX(Company_Latest!L$2:L$500, SMALL(IF((Company_Latest!$L$2:$L$500="OVERDUE (IDLE)")+(Company_Latest!$L$2:$L$500="WARNING (3-14 Days)"), ROW(Company_Latest!$L$2:$L$500)-1), 20)), "")
A30: =IF(B30<>"", 21, "") | B30: =IFERROR(INDEX(Company_Latest!C$2:C$500, SMALL(IF((Company_Latest!$L$2:$L$500="OVERDUE (IDLE)")+(Company_Latest!$L$2:$L$500="WARNING (3-14 Days)"), ROW(Company_Latest!$L$2:$L$500)-1), 21)), "") | C30: =IFERROR(INDEX(Company_Latest!D$2:D$500, SMALL(IF((Company_Latest!$L$2:$L$500="OVERDUE (IDLE)")+(Company_Latest!$L$2:$L$500="WARNING (3-14 Days)"), ROW(Company_Latest!$L$2:$L$500)-1), 21)), "") | D30: =IFERROR(INDEX(Company_Latest!E$2:E$500, SMALL(IF((Company_Latest!$L$2:$L$500="OVERDUE (IDLE)")+(Company_Latest!$L$2:$L$500="WARNING (3-14 Days)"), ROW(Company_Latest!$L$2:$L$500)-1), 21)), "") | E30: =IFERROR(INDEX(Company_Latest!G$2:G$500, SMALL(IF((Company_Latest!$L$2:$L$500="OVERDUE (IDLE)")+(Company_Latest!$L$2:$L$500="WARNING (3-14 Days)"), ROW(Company_Latest!$L$2:$L$500)-1), 21)), "") | F30: =IFERROR(INDEX(Company_Latest!H$2:H$500, SMALL(IF((Company_Latest!$L$2:$L$500="OVERDUE (IDLE)")+(Company_Latest!$L$2:$L$500="WARNING (3-14 Days)"), ROW(Company_Latest!$L$2:$L$500)-1), 21)), "") | G30: =IFERROR(INDEX(Company_Latest!K$2:K$500, SMALL(IF((Company_Latest!$L$2:$L$500="OVERDUE (IDLE)")+(Company_Latest!$L$2:$L$500="WARNING (3-14 Days)"), ROW(Company_Latest!$L$2:$L$500)-1), 21)), "") | H30: =IFERROR(INDEX(Company_Latest!L$2:L$500, SMALL(IF((Company_Latest!$L$2:$L$500="OVERDUE (IDLE)")+(Company_Latest!$L$2:$L$500="WARNING (3-14 Days)"), ROW(Company_Latest!$L$2:$L$500)-1), 21)), "")
A31: =IF(B31<>"", 22, "") | B31: =IFERROR(INDEX(Company_Latest!C$2:C$500, SMALL(IF((Company_Latest!$L$2:$L$500="OVERDUE (IDLE)")+(Company_Latest!$L$2:$L$500="WARNING (3-14 Days)"), ROW(Company_Latest!$L$2:$L$500)-1), 22)), "") | C31: =IFERROR(INDEX(Company_Latest!D$2:D$500, SMALL(IF((Company_Latest!$L$2:$L$500="OVERDUE (IDLE)")+(Company_Latest!$L$2:$L$500="WARNING (3-14 Days)"), ROW(Company_Latest!$L$2:$L$500)-1), 22)), "") | D31: =IFERROR(INDEX(Company_Latest!E$2:E$500, SMALL(IF((Company_Latest!$L$2:$L$500="OVERDUE (IDLE)")+(Company_Latest!$L$2:$L$500="WARNING (3-14 Days)"), ROW(Company_Latest!$L$2:$L$500)-1), 22)), "") | E31: =IFERROR(INDEX(Company_Latest!G$2:G$500, SMALL(IF((Company_Latest!$L$2:$L$500="OVERDUE (IDLE)")+(Company_Latest!$L$2:$L$500="WARNING (3-14 Days)"), ROW(Company_Latest!$L$2:$L$500)-1), 22)), "") | F31: =IFERROR(INDEX(Company_Latest!H$2:H$500, SMALL(IF((Company_Latest!$L$2:$L$500="OVERDUE (IDLE)")+(Company_Latest!$L$2:$L$500="WARNING (3-14 Days)"), ROW(Company_Latest!$L$2:$L$500)-1), 22)), "") | G31: =IFERROR(INDEX(Company_Latest!K$2:K$500, SMALL(IF((Company_Latest!$L$2:$L$500="OVERDUE (IDLE)")+(Company_Latest!$L$2:$L$500="WARNING (3-14 Days)"), ROW(Company_Latest!$L$2:$L$500)-1), 22)), "") | H31: =IFERROR(INDEX(Company_Latest!L$2:L$500, SMALL(IF((Company_Latest!$L$2:$L$500="OVERDUE (IDLE)")+(Company_Latest!$L$2:$L$500="WARNING (3-14 Days)"), ROW(Company_Latest!$L$2:$L$500)-1), 22)), "")
A32: =IF(B32<>"", 23, "") | B32: =IFERROR(INDEX(Company_Latest!C$2:C$500, SMALL(IF((Company_Latest!$L$2:$L$500="OVERDUE (IDLE)")+(Company_Latest!$L$2:$L$500="WARNING (3-14 Days)"), ROW(Company_Latest!$L$2:$L$500)-1), 23)), "") | C32: =IFERROR(INDEX(Company_Latest!D$2:D$500, SMALL(IF((Company_Latest!$L$2:$L$500="OVERDUE (IDLE)")+(Company_Latest!$L$2:$L$500="WARNING (3-14 Days)"), ROW(Company_Latest!$L$2:$L$500)-1), 23)), "") | D32: =IFERROR(INDEX(Company_Latest!E$2:E$500, SMALL(IF((Company_Latest!$L$2:$L$500="OVERDUE (IDLE)")+(Company_Latest!$L$2:$L$500="WARNING (3-14 Days)"), ROW(Company_Latest!$L$2:$L$500)-1), 23)), "") | E32: =IFERROR(INDEX(Company_Latest!G$2:G$500, SMALL(IF((Company_Latest!$L$2:$L$500="OVERDUE (IDLE)")+(Company_Latest!$L$2:$L$500="WARNING (3-14 Days)"), ROW(Company_Latest!$L$2:$L$500)-1), 23)), "") | F32: =IFERROR(INDEX(Company_Latest!H$2:H$500, SMALL(IF((Company_Latest!$L$2:$L$500="OVERDUE (IDLE)")+(Company_Latest!$L$2:$L$500="WARNING (3-14 Days)"), ROW(Company_Latest!$L$2:$L$500)-1), 23)), "") | G32: =IFERROR(INDEX(Company_Latest!K$2:K$500, SMALL(IF((Company_Latest!$L$2:$L$500="OVERDUE (IDLE)")+(Company_Latest!$L$2:$L$500="WARNING (3-14 Days)"), ROW(Company_Latest!$L$2:$L$500)-1), 23)), "") | H32: =IFERROR(INDEX(Company_Latest!L$2:L$500, SMALL(IF((Company_Latest!$L$2:$L$500="OVERDUE (IDLE)")+(Company_Latest!$L$2:$L$500="WARNING (3-14 Days)"), ROW(Company_Latest!$L$2:$L$500)-1), 23)), "")
A33: =IF(B33<>"", 24, "") | B33: =IFERROR(INDEX(Company_Latest!C$2:C$500, SMALL(IF((Company_Latest!$L$2:$L$500="OVERDUE (IDLE)")+(Company_Latest!$L$2:$L$500="WARNING (3-14 Days)"), ROW(Company_Latest!$L$2:$L$500)-1), 24)), "") | C33: =IFERROR(INDEX(Company_Latest!D$2:D$500, SMALL(IF((Company_Latest!$L$2:$L$500="OVERDUE (IDLE)")+(Company_Latest!$L$2:$L$500="WARNING (3-14 Days)"), ROW(Company_Latest!$L$2:$L$500)-1), 24)), "") | D33: =IFERROR(INDEX(Company_Latest!E$2:E$500, SMALL(IF((Company_Latest!$L$2:$L$500="OVERDUE (IDLE)")+(Company_Latest!$L$2:$L$500="WARNING (3-14 Days)"), ROW(Company_Latest!$L$2:$L$500)-1), 24)), "") | E33: =IFERROR(INDEX(Company_Latest!G$2:G$500, SMALL(IF((Company_Latest!$L$2:$L$500="OVERDUE (IDLE)")+(Company_Latest!$L$2:$L$500="WARNING (3-14 Days)"), ROW(Company_Latest!$L$2:$L$500)-1), 24)), "") | F33: =IFERROR(INDEX(Company_Latest!H$2:H$500, SMALL(IF((Company_Latest!$L$2:$L$500="OVERDUE (IDLE)")+(Company_Latest!$L$2:$L$500="WARNING (3-14 Days)"), ROW(Company_Latest!$L$2:$L$500)-1), 24)), "") | G33: =IFERROR(INDEX(Company_Latest!K$2:K$500, SMALL(IF((Company_Latest!$L$2:$L$500="OVERDUE (IDLE)")+(Company_Latest!$L$2:$L$500="WARNING (3-14 Days)"), ROW(Company_Latest!$L$2:$L$500)-1), 24)), "") | H33: =IFERROR(INDEX(Company_Latest!L$2:L$500, SMALL(IF((Company_Latest!$L$2:$L$500="OVERDUE (IDLE)")+(Company_Latest!$L$2:$L$500="WARNING (3-14 Days)"), ROW(Company_Latest!$L$2:$L$500)-1), 24)), "")
A34: =IF(B34<>"", 25, "") | B34: =IFERROR(INDEX(Company_Latest!C$2:C$500, SMALL(IF((Company_Latest!$L$2:$L$500="OVERDUE (IDLE)")+(Company_Latest!$L$2:$L$500="WARNING (3-14 Days)"), ROW(Company_Latest!$L$2:$L$500)-1), 25)), "") | C34: =IFERROR(INDEX(Company_Latest!D$2:D$500, SMALL(IF((Company_Latest!$L$2:$L$500="OVERDUE (IDLE)")+(Company_Latest!$L$2:$L$500="WARNING (3-14 Days)"), ROW(Company_Latest!$L$2:$L$500)-1), 25)), "") | D34: =IFERROR(INDEX(Company_Latest!E$2:E$500, SMALL(IF((Company_Latest!$L$2:$L$500="OVERDUE (IDLE)")+(Company_Latest!$L$2:$L$500="WARNING (3-14 Days)"), ROW(Company_Latest!$L$2:$L$500)-1), 25)), "") | E34: =IFERROR(INDEX(Company_Latest!G$2:G$500, SMALL(IF((Company_Latest!$L$2:$L$500="OVERDUE (IDLE)")+(Company_Latest!$L$2:$L$500="WARNING (3-14 Days)"), ROW(Company_Latest!$L$2:$L$500)-1), 25)), "") | F34: =IFERROR(INDEX(Company_Latest!H$2:H$500, SMALL(IF((Company_Latest!$L$2:$L$500="OVERDUE (IDLE)")+(Company_Latest!$L$2:$L$500="WARNING (3-14 Days)"), ROW(Company_Latest!$L$2:$L$500)-1), 25)), "") | G34: =IFERROR(INDEX(Company_Latest!K$2:K$500, SMALL(IF((Company_Latest!$L$2:$L$500="OVERDUE (IDLE)")+(Company_Latest!$L$2:$L$500="WARNING (3-14 Days)"), ROW(Company_Latest!$L$2:$L$500)-1), 25)), "") | H34: =IFERROR(INDEX(Company_Latest!L$2:L$500, SMALL(IF((Company_Latest!$L$2:$L$500="OVERDUE (IDLE)")+(Company_Latest!$L$2:$L$500="WARNING (3-14 Days)"), ROW(Company_Latest!$L$2:$L$500)-1), 25)), "")
A35: =IF(B35<>"", 26, "") | B35: =IFERROR(INDEX(Company_Latest!C$2:C$500, SMALL(IF((Company_Latest!$L$2:$L$500="OVERDUE (IDLE)")+(Company_Latest!$L$2:$L$500="WARNING (3-14 Days)"), ROW(Company_Latest!$L$2:$L$500)-1), 26)), "") | C35: =IFERROR(INDEX(Company_Latest!D$2:D$500, SMALL(IF((Company_Latest!$L$2:$L$500="OVERDUE (IDLE)")+(Company_Latest!$L$2:$L$500="WARNING (3-14 Days)"), ROW(Company_Latest!$L$2:$L$500)-1), 26)), "") | D35: =IFERROR(INDEX(Company_Latest!E$2:E$500, SMALL(IF((Company_Latest!$L$2:$L$500="OVERDUE (IDLE)")+(Company_Latest!$L$2:$L$500="WARNING (3-14 Days)"), ROW(Company_Latest!$L$2:$L$500)-1), 26)), "") | E35: =IFERROR(INDEX(Company_Latest!G$2:G$500, SMALL(IF((Company_Latest!$L$2:$L$500="OVERDUE (IDLE)")+(Company_Latest!$L$2:$L$500="WARNING (3-14 Days)"), ROW(Company_Latest!$L$2:$L$500)-1), 26)), "") | F35: =IFERROR(INDEX(Company_Latest!H$2:H$500, SMALL(IF((Company_Latest!$L$2:$L$500="OVERDUE (IDLE)")+(Company_Latest!$L$2:$L$500="WARNING (3-14 Days)"), ROW(Company_Latest!$L$2:$L$500)-1), 26)), "") | G35: =IFERROR(INDEX(Company_Latest!K$2:K$500, SMALL(IF((Company_Latest!$L$2:$L$500="OVERDUE (IDLE)")+(Company_Latest!$L$2:$L$500="WARNING (3-14 Days)"), ROW(Company_Latest!$L$2:$L$500)-1), 26)), "") | H35: =IFERROR(INDEX(Company_Latest!L$2:L$500, SMALL(IF((Company_Latest!$L$2:$L$500="OVERDUE (IDLE)")+(Company_Latest!$L$2:$L$500="WARNING (3-14 Days)"), ROW(Company_Latest!$L$2:$L$500)-1), 26)), "")
A36: =IF(B36<>"", 27, "") | B36: =IFERROR(INDEX(Company_Latest!C$2:C$500, SMALL(IF((Company_Latest!$L$2:$L$500="OVERDUE (IDLE)")+(Company_Latest!$L$2:$L$500="WARNING (3-14 Days)"), ROW(Company_Latest!$L$2:$L$500)-1), 27)), "") | C36: =IFERROR(INDEX(Company_Latest!D$2:D$500, SMALL(IF((Company_Latest!$L$2:$L$500="OVERDUE (IDLE)")+(Company_Latest!$L$2:$L$500="WARNING (3-14 Days)"), ROW(Company_Latest!$L$2:$L$500)-1), 27)), "") | D36: =IFERROR(INDEX(Company_Latest!E$2:E$500, SMALL(IF((Company_Latest!$L$2:$L$500="OVERDUE (IDLE)")+(Company_Latest!$L$2:$L$500="WARNING (3-14 Days)"), ROW(Company_Latest!$L$2:$L$500)-1), 27)), "") | E36: =IFERROR(INDEX(Company_Latest!G$2:G$500, SMALL(IF((Company_Latest!$L$2:$L$500="OVERDUE (IDLE)")+(Company_Latest!$L$2:$L$500="WARNING (3-14 Days)"), ROW(Company_Latest!$L$2:$L$500)-1), 27)), "") | F36: =IFERROR(INDEX(Company_Latest!H$2:H$500, SMALL(IF((Company_Latest!$L$2:$L$500="OVERDUE (IDLE)")+(Company_Latest!$L$2:$L$500="WARNING (3-14 Days)"), ROW(Company_Latest!$L$2:$L$500)-1), 27)), "") | G36: =IFERROR(INDEX(Company_Latest!K$2:K$500, SMALL(IF((Company_Latest!$L$2:$L$500="OVERDUE (IDLE)")+(Company_Latest!$L$2:$L$500="WARNING (3-14 Days)"), ROW(Company_Latest!$L$2:$L$500)-1), 27)), "") | H36: =IFERROR(INDEX(Company_Latest!L$2:L$500, SMALL(IF((Company_Latest!$L$2:$L$500="OVERDUE (IDLE)")+(Company_Latest!$L$2:$L$500="WARNING (3-14 Days)"), ROW(Company_Latest!$L$2:$L$500)-1), 27)), "")
A37: =IF(B37<>"", 28, "") | B37: =IFERROR(INDEX(Company_Latest!C$2:C$500, SMALL(IF((Company_Latest!$L$2:$L$500="OVERDUE (IDLE)")+(Company_Latest!$L$2:$L$500="WARNING (3-14 Days)"), ROW(Company_Latest!$L$2:$L$500)-1), 28)), "") | C37: =IFERROR(INDEX(Company_Latest!D$2:D$500, SMALL(IF((Company_Latest!$L$2:$L$500="OVERDUE (IDLE)")+(Company_Latest!$L$2:$L$500="WARNING (3-14 Days)"), ROW(Company_Latest!$L$2:$L$500)-1), 28)), "") | D37: =IFERROR(INDEX(Company_Latest!E$2:E$500, SMALL(IF((Company_Latest!$L$2:$L$500="OVERDUE (IDLE)")+(Company_Latest!$L$2:$L$500="WARNING (3-14 Days)"), ROW(Company_Latest!$L$2:$L$500)-1), 28)), "") | E37: =IFERROR(INDEX(Company_Latest!G$2:G$500, SMALL(IF((Company_Latest!$L$2:$L$500="OVERDUE (IDLE)")+(Company_Latest!$L$2:$L$500="WARNING (3-14 Days)"), ROW(Company_Latest!$L$2:$L$500)-1), 28)), "") | F37: =IFERROR(INDEX(Company_Latest!H$2:H$500, SMALL(IF((Company_Latest!$L$2:$L$500="OVERDUE (IDLE)")+(Company_Latest!$L$2:$L$500="WARNING (3-14 Days)"), ROW(Company_Latest!$L$2:$L$500)-1), 28)), "") | G37: =IFERROR(INDEX(Company_Latest!K$2:K$500, SMALL(IF((Company_Latest!$L$2:$L$500="OVERDUE (IDLE)")+(Company_Latest!$L$2:$L$500="WARNING (3-14 Days)"), ROW(Company_Latest!$L$2:$L$500)-1), 28)), "") | H37: =IFERROR(INDEX(Company_Latest!L$2:L$500, SMALL(IF((Company_Latest!$L$2:$L$500="OVERDUE (IDLE)")+(Company_Latest!$L$2:$L$500="WARNING (3-14 Days)"), ROW(Company_Latest!$L$2:$L$500)-1), 28)), "")
A38: =IF(B38<>"", 29, "") | B38: =IFERROR(INDEX(Company_Latest!C$2:C$500, SMALL(IF((Company_Latest!$L$2:$L$500="OVERDUE (IDLE)")+(Company_Latest!$L$2:$L$500="WARNING (3-14 Days)"), ROW(Company_Latest!$L$2:$L$500)-1), 29)), "") | C38: =IFERROR(INDEX(Company_Latest!D$2:D$500, SMALL(IF((Company_Latest!$L$2:$L$500="OVERDUE (IDLE)")+(Company_Latest!$L$2:$L$500="WARNING (3-14 Days)"), ROW(Company_Latest!$L$2:$L$500)-1), 29)), "") | D38: =IFERROR(INDEX(Company_Latest!E$2:E$500, SMALL(IF((Company_Latest!$L$2:$L$500="OVERDUE (IDLE)")+(Company_Latest!$L$2:$L$500="WARNING (3-14 Days)"), ROW(Company_Latest!$L$2:$L$500)-1), 29)), "") | E38: =IFERROR(INDEX(Company_Latest!G$2:G$500, SMALL(IF((Company_Latest!$L$2:$L$500="OVERDUE (IDLE)")+(Company_Latest!$L$2:$L$500="WARNING (3-14 Days)"), ROW(Company_Latest!$L$2:$L$500)-1), 29)), "") | F38: =IFERROR(INDEX(Company_Latest!H$2:H$500, SMALL(IF((Company_Latest!$L$2:$L$500="OVERDUE (IDLE)")+(Company_Latest!$L$2:$L$500="WARNING (3-14 Days)"), ROW(Company_Latest!$L$2:$L$500)-1), 29)), "") | G38: =IFERROR(INDEX(Company_Latest!K$2:K$500, SMALL(IF((Company_Latest!$L$2:$L$500="OVERDUE (IDLE)")+(Company_Latest!$L$2:$L$500="WARNING (3-14 Days)"), ROW(Company_Latest!$L$2:$L$500)-1), 29)), "") | H38: =IFERROR(INDEX(Company_Latest!L$2:L$500, SMALL(IF((Company_Latest!$L$2:$L$500="OVERDUE (IDLE)")+(Company_Latest!$L$2:$L$500="WARNING (3-14 Days)"), ROW(Company_Latest!$L$2:$L$500)-1), 29)), "")
A39: =IF(B39<>"", 30, "") | B39: =IFERROR(INDEX(Company_Latest!C$2:C$500, SMALL(IF((Company_Latest!$L$2:$L$500="OVERDUE (IDLE)")+(Company_Latest!$L$2:$L$500="WARNING (3-14 Days)"), ROW(Company_Latest!$L$2:$L$500)-1), 30)), "") | C39: =IFERROR(INDEX(Company_Latest!D$2:D$500, SMALL(IF((Company_Latest!$L$2:$L$500="OVERDUE (IDLE)")+(Company_Latest!$L$2:$L$500="WARNING (3-14 Days)"), ROW(Company_Latest!$L$2:$L$500)-1), 30)), "") | D39: =IFERROR(INDEX(Company_Latest!E$2:E$500, SMALL(IF((Company_Latest!$L$2:$L$500="OVERDUE (IDLE)")+(Company_Latest!$L$2:$L$500="WARNING (3-14 Days)"), ROW(Company_Latest!$L$2:$L$500)-1), 30)), "") | E39: =IFERROR(INDEX(Company_Latest!G$2:G$500, SMALL(IF((Company_Latest!$L$2:$L$500="OVERDUE (IDLE)")+(Company_Latest!$L$2:$L$500="WARNING (3-14 Days)"), ROW(Company_Latest!$L$2:$L$500)-1), 30)), "") | F39: =IFERROR(INDEX(Company_Latest!H$2:H$500, SMALL(IF((Company_Latest!$L$2:$L$500="OVERDUE (IDLE)")+(Company_Latest!$L$2:$L$500="WARNING (3-14 Days)"), ROW(Company_Latest!$L$2:$L$500)-1), 30)), "") | G39: =IFERROR(INDEX(Company_Latest!K$2:K$500, SMALL(IF((Company_Latest!$L$2:$L$500="OVERDUE (IDLE)")+(Company_Latest!$L$2:$L$500="WARNING (3-14 Days)"), ROW(Company_Latest!$L$2:$L$500)-1), 30)), "") | H39: =IFERROR(INDEX(Company_Latest!L$2:L$500, SMALL(IF((Company_Latest!$L$2:$L$500="OVERDUE (IDLE)")+(Company_Latest!$L$2:$L$500="WARNING (3-14 Days)"), ROW(Company_Latest!$L$2:$L$500)-1), 30)), "")
A40: =IF(B40<>"", 31, "") | B40: =IFERROR(INDEX(Company_Latest!C$2:C$500, SMALL(IF((Company_Latest!$L$2:$L$500="OVERDUE (IDLE)")+(Company_Latest!$L$2:$L$500="WARNING (3-14 Days)"), ROW(Company_Latest!$L$2:$L$500)-1), 31)), "") | C40: =IFERROR(INDEX(Company_Latest!D$2:D$500, SMALL(IF((Company_Latest!$L$2:$L$500="OVERDUE (IDLE)")+(Company_Latest!$L$2:$L$500="WARNING (3-14 Days)"), ROW(Company_Latest!$L$2:$L$500)-1), 31)), "") | D40: =IFERROR(INDEX(Company_Latest!E$2:E$500, SMALL(IF((Company_Latest!$L$2:$L$500="OVERDUE (IDLE)")+(Company_Latest!$L$2:$L$500="WARNING (3-14 Days)"), ROW(Company_Latest!$L$2:$L$500)-1), 31)), "") | E40: =IFERROR(INDEX(Company_Latest!G$2:G$500, SMALL(IF((Company_Latest!$L$2:$L$500="OVERDUE (IDLE)")+(Company_Latest!$L$2:$L$500="WARNING (3-14 Days)"), ROW(Company_Latest!$L$2:$L$500)-1), 31)), "") | F40: =IFERROR(INDEX(Company_Latest!H$2:H$500, SMALL(IF((Company_Latest!$L$2:$L$500="OVERDUE (IDLE)")+(Company_Latest!$L$2:$L$500="WARNING (3-14 Days)"), ROW(Company_Latest!$L$2:$L$500)-1), 31)), "") | G40: =IFERROR(INDEX(Company_Latest!K$2:K$500, SMALL(IF((Company_Latest!$L$2:$L$500="OVERDUE (IDLE)")+(Company_Latest!$L$2:$L$500="WARNING (3-14 Days)"), ROW(Company_Latest!$L$2:$L$500)-1), 31)), "") | H40: =IFERROR(INDEX(Company_Latest!L$2:L$500, SMALL(IF((Company_Latest!$L$2:$L$500="OVERDUE (IDLE)")+(Company_Latest!$L$2:$L$500="WARNING (3-14 Days)"), ROW(Company_Latest!$L$2:$L$500)-1), 31)), "")
A41: =IF(B41<>"", 32, "") | B41: =IFERROR(INDEX(Company_Latest!C$2:C$500, SMALL(IF((Company_Latest!$L$2:$L$500="OVERDUE (IDLE)")+(Company_Latest!$L$2:$L$500="WARNING (3-14 Days)"), ROW(Company_Latest!$L$2:$L$500)-1), 32)), "") | C41: =IFERROR(INDEX(Company_Latest!D$2:D$500, SMALL(IF((Company_Latest!$L$2:$L$500="OVERDUE (IDLE)")+(Company_Latest!$L$2:$L$500="WARNING (3-14 Days)"), ROW(Company_Latest!$L$2:$L$500)-1), 32)), "") | D41: =IFERROR(INDEX(Company_Latest!E$2:E$500, SMALL(IF((Company_Latest!$L$2:$L$500="OVERDUE (IDLE)")+(Company_Latest!$L$2:$L$500="WARNING (3-14 Days)"), ROW(Company_Latest!$L$2:$L$500)-1), 32)), "") | E41: =IFERROR(INDEX(Company_Latest!G$2:G$500, SMALL(IF((Company_Latest!$L$2:$L$500="OVERDUE (IDLE)")+(Company_Latest!$L$2:$L$500="WARNING (3-14 Days)"), ROW(Company_Latest!$L$2:$L$500)-1), 32)), "") | F41: =IFERROR(INDEX(Company_Latest!H$2:H$500, SMALL(IF((Company_Latest!$L$2:$L$500="OVERDUE (IDLE)")+(Company_Latest!$L$2:$L$500="WARNING (3-14 Days)"), ROW(Company_Latest!$L$2:$L$500)-1), 32)), "") | G41: =IFERROR(INDEX(Company_Latest!K$2:K$500, SMALL(IF((Company_Latest!$L$2:$L$500="OVERDUE (IDLE)")+(Company_Latest!$L$2:$L$500="WARNING (3-14 Days)"), ROW(Company_Latest!$L$2:$L$500)-1), 32)), "") | H41: =IFERROR(INDEX(Company_Latest!L$2:L$500, SMALL(IF((Company_Latest!$L$2:$L$500="OVERDUE (IDLE)")+(Company_Latest!$L$2:$L$500="WARNING (3-14 Days)"), ROW(Company_Latest!$L$2:$L$500)-1), 32)), "")
A42: =IF(B42<>"", 33, "") | B42: =IFERROR(INDEX(Company_Latest!C$2:C$500, SMALL(IF((Company_Latest!$L$2:$L$500="OVERDUE (IDLE)")+(Company_Latest!$L$2:$L$500="WARNING (3-14 Days)"), ROW(Company_Latest!$L$2:$L$500)-1), 33)), "") | C42: =IFERROR(INDEX(Company_Latest!D$2:D$500, SMALL(IF((Company_Latest!$L$2:$L$500="OVERDUE (IDLE)")+(Company_Latest!$L$2:$L$500="WARNING (3-14 Days)"), ROW(Company_Latest!$L$2:$L$500)-1), 33)), "") | D42: =IFERROR(INDEX(Company_Latest!E$2:E$500, SMALL(IF((Company_Latest!$L$2:$L$500="OVERDUE (IDLE)")+(Company_Latest!$L$2:$L$500="WARNING (3-14 Days)"), ROW(Company_Latest!$L$2:$L$500)-1), 33)), "") | E42: =IFERROR(INDEX(Company_Latest!G$2:G$500, SMALL(IF((Company_Latest!$L$2:$L$500="OVERDUE (IDLE)")+(Company_Latest!$L$2:$L$500="WARNING (3-14 Days)"), ROW(Company_Latest!$L$2:$L$500)-1), 33)), "") | F42: =IFERROR(INDEX(Company_Latest!H$2:H$500, SMALL(IF((Company_Latest!$L$2:$L$500="OVERDUE (IDLE)")+(Company_Latest!$L$2:$L$500="WARNING (3-14 Days)"), ROW(Company_Latest!$L$2:$L$500)-1), 33)), "") | G42: =IFERROR(INDEX(Company_Latest!K$2:K$500, SMALL(IF((Company_Latest!$L$2:$L$500="OVERDUE (IDLE)")+(Company_Latest!$L$2:$L$500="WARNING (3-14 Days)"), ROW(Company_Latest!$L$2:$L$500)-1), 33)), "") | H42: =IFERROR(INDEX(Company_Latest!L$2:L$500, SMALL(IF((Company_Latest!$L$2:$L$500="OVERDUE (IDLE)")+(Company_Latest!$L$2:$L$500="WARNING (3-14 Days)"), ROW(Company_Latest!$L$2:$L$500)-1), 33)), "")
...

Sheet Company_Latest
A1: Sales Manager | B1: Sales Supervisor | C1: Sales Officer | D1: Company ID | E1: Company Name | F1: Company Size | G1: Project ID | H1: Last Progress | I1: Prospect to Leads (Left Days) | J1: Leads to Idle (Left Days) | K1: Detail Progress & Note | L1: Alert Status
A2: Fuji | C2: Ravico | D2: EMPIND | E2: EIGERINDO MULTI PRODUK INDONESIA | F2: L | G2: 7.25.00362 | H2: Leads | I2: 0 | J2: -32 | K2: Reach Truck 1.5 Ton (1 Unit) _ 1 Tahun _ Canvassing awal & Sales Call | L2: =IF(AND(H2="Leads", J2<=0), "OVERDUE (IDLE)", IF(AND(H2="Leads", J2<=14), "WARNING (3-14 Days)", IF(AND(H2="Prospect", J2<=0), "PROSPECT EXPIRED", "SAFE / ON TRACK")))
A3: Fuji | C3: Ravico | D3: BCCBI | E3: PT BANK CHINA CONSTRUCTION BANK INDONESIA TBK | F3: L | G3: 7.26.00053 | H3: Leads | I3: 0 | J3: 21 | K3: Reach Truck 1.5 Ton (1 Unit) _ 1 Tahun _ Canvassing awal & Sales Call | L3: =IF(AND(H3="Leads", J3<=0), "OVERDUE (IDLE)", IF(AND(H3="Leads", J3<=14), "WARNING (3-14 Days)", IF(AND(H3="Prospect", J3<=0), "PROSPECT EXPIRED", "SAFE / ON TRACK")))
A4: Fuji | C4: Ravico | D4: TRITNGGAL | E4: PT TRITUNGGAL DELTA SEJAHTERA | F4: M | G4: 7.26.00116 | H4: Leads | I4: 0 | J4: 28 | K4: Reach Truck 1.5 Ton (1 Unit) _ 1 Tahun _ Canvassing awal & Sales Call | L4: =IF(AND(H4="Leads", J4<=0), "OVERDUE (IDLE)", IF(AND(H4="Leads", J4<=14), "WARNING (3-14 Days)", IF(AND(H4="Prospect", J4<=0), "PROSPECT EXPIRED", "SAFE / ON TRACK")))
A5: Fuji | C5: Ravico | D5: UPD | E5: PT UNITRADE PRIMA DINAMIKA | F5: M | G5: 7.26.00317 | H5: Leads | I5: 0 | J5: 94 | K5: Reach Truck 1.5 Ton (1 Unit) _ 1 Tahun _ Canvassing awal & Sales Call | L5: =IF(AND(H5="Leads", J5<=0), "OVERDUE (IDLE)", IF(AND(H5="Leads", J5<=14), "WARNING (3-14 Days)", IF(AND(H5="Prospect", J5<=0), "PROSPECT EXPIRED", "SAFE / ON TRACK")))
A6: Fuji | C6: Ravico | D6: ONIND | E6: PT ONINDONESIA SISTEM TEKNOLOGI | F6: M | G6: 7.26.00319 | H6: Leads | I6: 0 | J6: 100 | K6: Reach Truck 1.5 Ton (1 Unit) _ 1 Tahun _ Canvassing awal & Sales Call | L6: =IF(AND(H6="Leads", J6<=0), "OVERDUE (IDLE)", IF(AND(H6="Leads", J6<=14), "WARNING (3-14 Days)", IF(AND(H6="Prospect", J6<=0), "PROSPECT EXPIRED", "SAFE / ON TRACK")))
A7: Fuji | C7: Ravico | D7: ASUTOMARIN | E7: PT ASURANSI TOKIO MARINE INDONESIA | F7: L | G7: 7.26.00324 | H7: Leads | I7: 0 | J7: 112 | K7: Reach Truck 1.5 Ton (1 Unit) _ 1 Tahun _ Canvassing awal & Sales Call | L7: =IF(AND(H7="Leads", J7<=0), "OVERDUE (IDLE)", IF(AND(H7="Leads", J7<=14), "WARNING (3-14 Days)", IF(AND(H7="Prospect", J7<=0), "PROSPECT EXPIRED", "SAFE / ON TRACK")))
A8: Fuji | C8: Ravico | D8: NELY | E8: PT PELAYARAN NELLY DWI PUTRI TBK | F8: L | G8: 7.26.00328 | H8: Leads | I8: 0 | J8: 16 | K8: Reach Truck 1.5 Ton (1 Unit) _ 1 Tahun _ Canvassing awal & Sales Call | L8: =IF(AND(H8="Leads", J8<=0), "OVERDUE (IDLE)", IF(AND(H8="Leads", J8<=14), "WARNING (3-14 Days)", IF(AND(H8="Prospect", J8<=0), "PROSPECT EXPIRED", "SAFE / ON TRACK")))
A9: Fuji | C9: Ravico | D9: PNGGIDN | E9: PT PINANG EXPORT INDONESIA | F9: M | G9: 7.26.00329 | H9: Leads | I9: 0 | J9: 127 | K9: Reach Truck 1.5 Ton (1 Unit) _ 1 Tahun _ Canvassing awal & Sales Call | L9: =IF(AND(H9="Leads", J9<=0), "OVERDUE (IDLE)", IF(AND(H9="Leads", J9<=14), "WARNING (3-14 Days)", IF(AND(H9="Prospect", J9<=0), "PROSPECT EXPIRED", "SAFE / ON TRACK")))
A10: Fuji | C10: Ravico | D10: CKDMI | E10: PT CKD MANUFACTURING INDONESIA | F10: M | G10: 7.26.00336 | H10: Leads | I10: 0 | J10: 17 | K10: Reach Truck 1.5 Ton (1 Unit) _ 1 Tahun _ Canvassing awal & Sales Call | L10: =IF(AND(H10="Leads", J10<=0), "OVERDUE (IDLE)", IF(AND(H10="Leads", J10<=14), "WARNING (3-14 Days)", IF(AND(H10="Prospect", J10<=0), "PROSPECT EXPIRED", "SAFE / ON TRACK")))
A11: Fuji | C11: Ravico | D11: SECO | E11: PT SECO TOOLS INDONESIA | F11: M | G11: 7.26.00337 | H11: Leads | I11: 0 | J11: 17 | K11: Reach Truck 1.5 Ton (1 Unit) _ 1 Tahun _ Canvassing awal & Sales Call | L11: =IF(AND(H11="Leads", J11<=0), "OVERDUE (IDLE)", IF(AND(H11="Leads", J11<=14), "WARNING (3-14 Days)", IF(AND(H11="Prospect", J11<=0), "PROSPECT EXPIRED", "SAFE / ON TRACK")))
A12: Fuji | C12: Ravico | D12: KYOUEI | E12: PT INDONESIA KYOUEI SAIKYU | F12: M | G12: 7.26.00351 | H12: Leads | I12: 0 | J12: 23 | K12: Reach Truck 1.5 Ton (1 Unit) _ 1 Tahun _ Canvassing awal & Sales Call | L12: =IF(AND(H12="Leads", J12<=0), "OVERDUE (IDLE)", IF(AND(H12="Leads", J12<=14), "WARNING (3-14 Days)", IF(AND(H12="Prospect", J12<=0), "PROSPECT EXPIRED", "SAFE / ON TRACK")))
A13: Fuji | C13: Ravico | D13: IDKIND | E13: PT IDAKA INDONESIA | F13: M | G13: 7.26.00352 | H13: Leads | I13: 0 | J13: 23 | K13: Reach Truck 1.5 Ton (1 Unit) _ 1 Tahun _ Canvassing awal & Sales Call | L13: =IF(AND(H13="Leads", J13<=0), "OVERDUE (IDLE)", IF(AND(H13="Leads", J13<=14), "WARNING (3-14 Days)", IF(AND(H13="Prospect", J13<=0), "PROSPECT EXPIRED", "SAFE / ON TRACK")))
... A24: Fuji | C24: Ravico | D24: AGSI | E24: PT ANEKA GAS INDUSTRI TBK | F24: S | G24: 7.26.00396 | H24: Leads | I24: 0 | J24: 29 | K24: Reach Truck 1.5 Ton (1 Unit) _ 1 Tahun _ Canvassing awal & Sales Call | L24: =IF(AND(H24="Leads", J24<=0), "OVERDUE (IDLE)", IF(AND(H24="Leads", J24<=14), "WARNING (3-14 Days)", IF(AND(H24="Prospect", J24<=0), "PROSPECT EXPIRED", "SAFE / ON TRACK")))
A25: Fuji | C25: Ravico | D25: DAG | E25: DARMAWAN ARYANSYAH GROUP | G25: 7.26.00415 | H25: Leads | I25: 0 | J25: 29 | K25: Reach Truck 1.5 Ton (1 Unit) _ 1 Tahun _ Canvassing awal & Sales Call | L25: =IF(AND(H25="Leads", J25<=0), "OVERDUE (IDLE)", IF(AND(H25="Leads", J25<=14), "WARNING (3-14 Days)", IF(AND(H25="Prospect", J25<=0), "PROSPECT EXPIRED", "SAFE / ON TRACK")))
A26: Fuji | C26: Ravico | D26: GRANDMC | E26: GRAND MULTI CHEMICALS | F26: S | G26: 7.26.00430 | H26: Leads | I26: 0 | J26: 29 | K26: Reach Truck 1.5 Ton (1 Unit) _ 1 Tahun _ Canvassing awal & Sales Call | L26: =IF(AND(H26="Leads", J26<=0), "OVERDUE (IDLE)", IF(AND(H26="Leads", J26<=14), "WARNING (3-14 Days)", IF(AND(H26="Prospect", J26<=0), "PROSPECT EXPIRED", "SAFE / ON TRACK")))
A27: Fuji | C27: Ravico | D27: INDOCEMENT | E27: PT INDOCEMENT TUNGGAL PRAKARSA TBK | F27: L | G27: 7.26.00451 | H27: Leads | I27: 0 | J27: 29 | K27: Reach Truck 1.5 Ton (1 Unit) _ 1 Tahun _ Canvassing awal & Sales Call | L27: =IF(AND(H27="Leads", J27<=0), "OVERDUE (IDLE)", IF(AND(H27="Leads", J27<=14), "WARNING (3-14 Days)", IF(AND(H27="Prospect", J27<=0), "PROSPECT EXPIRED", "SAFE / ON TRACK")))
A28: Fuji | C28: Ravico | D28: INTIKARYAP | E28: INTI KARYA PERSADA TEHNIK | F28: L | G28: 7.26.00463 | H28: Leads | I28: 0 | J28: 29 | K28: Reach Truck 1.5 Ton (1 Unit) _ 1 Tahun _ Canvassing awal & Sales Call | L28: =IF(AND(H28="Leads", J28<=0), "OVERDUE (IDLE)", IF(AND(H28="Leads", J28<=14), "WARNING (3-14 Days)", IF(AND(H28="Prospect", J28<=0), "PROSPECT EXPIRED", "SAFE / ON TRACK")))
A29: Fuji | C29: Ravico | D29: ITOKI | E29: ITOKI SOLUTIONS INDONESIA | G29: 7.26.00465 | H29: Leads | I29: 0 | J29: 29 | K29: Reach Truck 1.5 Ton (1 Unit) _ 1 Tahun _ Canvassing awal & Sales Call | L29: =IF(AND(H29="Leads", J29<=0), "OVERDUE (IDLE)", IF(AND(H29="Leads", J29<=14), "WARNING (3-14 Days)", IF(AND(H29="Prospect", J29<=0), "PROSPECT EXPIRED", "SAFE / ON TRACK")))
A30: Fuji | C30: Ravico | D30: JAWASATU | E30: JAWA SATU POWER | G30: 7.26.00467 | H30: Leads | I30: 0 | J30: 29 | K30: Reach Truck 1.5 Ton (1 Unit) _ 1 Tahun _ Canvassing awal & Sales Call | L30: =IF(AND(H30="Leads", J30<=0), "OVERDUE (IDLE)", IF(AND(H30="Leads", J30<=14), "WARNING (3-14 Days)", IF(AND(H30="Prospect", J30<=0), "PROSPECT EXPIRED", "SAFE / ON TRACK")))
A31: Fuji | C31: Ravico | D31: GRAHABARA | E31: GRAHA BARA LESTARI | G31: 7.26.00513 | H31: Leads | I31: 0 | J31: 36 | K31: Reach Truck 1.5 Ton (1 Unit) _ 1 Tahun _ Canvassing awal & Sales Call | L31: =IF(AND(H31="Leads", J31<=0), "OVERDUE (IDLE)", IF(AND(H31="Leads", J31<=14), "WARNING (3-14 Days)", IF(AND(H31="Prospect", J31<=0), "PROSPECT EXPIRED", "SAFE / ON TRACK")))
A32: Fuji | C32: Ravico | D32: JADDIINTER | E32: JADDI INTERNASIONAL | G32: 7.26.00519 | H32: Leads | I32: 0 | J32: 36 | K32: Reach Truck 1.5 Ton (1 Unit) _ 1 Tahun _ Canvassing awal & Sales Call | L32: =IF(AND(H32="Leads", J32<=0), "OVERDUE (IDLE)", IF(AND(H32="Leads", J32<=14), "WARNING (3-14 Days)", IF(AND(H32="Prospect", J32<=0), "PROSPECT EXPIRED", "SAFE / ON TRACK")))
A33: Fuji | C33: Ravico | D33: UNGGULBUDI | E33: PT UNGGUL BUDI LESTARI | F33: L | G33: 7.26.00576 | H33: Leads | I33: 0 | J33: 43 | K33: Reach Truck 1.5 Ton (1 Unit) _ 1 Tahun _ Canvassing awal & Sales Call | L33: =IF(AND(H33="Leads", J33<=0), "OVERDUE (IDLE)", IF(AND(H33="Leads", J33<=14), "WARNING (3-14 Days)", IF(AND(H33="Prospect", J33<=0), "PROSPECT EXPIRED", "SAFE / ON TRACK")))
A34: Fuji | C34: Ravico | D34: LOGICOM | E34: PT LOGICOM CAKRA INDONESIA | F34: M | G34: 7.26.00588 | H34: Leads | I34: 0 | J34: 50 | K34: Reach Truck 1.5 Ton (1 Unit) _ 1 Tahun _ Canvassing awal & Sales Call | L34: =IF(AND(H34="Leads", J34<=0), "OVERDUE (IDLE)", IF(AND(H34="Leads", J34<=14), "WARNING (3-14 Days)", IF(AND(H34="Prospect", J34<=0), "PROSPECT EXPIRED", "SAFE / ON TRACK")))
A35: Fuji | C35: Ravico | D35: PPPT | E35: PT POLYMINDO PERMATA | F35: M | G35: 7.26.00593 | H35: Leads | I35: 0 | J35: 52 | K35: Reach Truck 1.5 Ton (1 Unit) _ 1 Tahun _ Canvassing awal & Sales Call | L35: =IF(AND(H35="Leads", J35<=0), "OVERDUE (IDLE)", IF(AND(H35="Leads", J35<=14), "WARNING (3-14 Days)", IF(AND(H35="Prospect", J35<=0), "PROSPECT EXPIRED", "SAFE / ON TRACK")))
A36: Fuji | C36: Ravico | D36: AYODYA | E36: PT AYODYA DIALOG SEMESTA | F36: M | G36: 7.26.00612 | H36: Leads | I36: 0 | J36: 59 | K36: Reach Truck 1.5 Ton (1 Unit) _ 1 Tahun _ Canvassing awal & Sales Call | L36: =IF(AND(H36="Leads", J36<=0), "OVERDUE (IDLE)", IF(AND(H36="Leads", J36<=14), "WARNING (3-14 Days)", IF(AND(H36="Prospect", J36<=0), "PROSPECT EXPIRED", "SAFE / ON TRACK")))
A37: Fuji | C37: Ravico | D37: FOTEC | E37: PT FOTEC INTER MAKMUR | F37: M | G37: 7.26.00613 | H37: Leads | I37: 0 | J37: 59 | K37: Reach Truck 1.5 Ton (1 Unit) _ 1 Tahun _ Canvassing awal & Sales Call | L37: =IF(AND(H37="Leads", J37<=0), "OVERDUE (IDLE)", IF(AND(H37="Leads", J37<=14), "WARNING (3-14 Days)", IF(AND(H37="Prospect", J37<=0), "PROSPECT EXPIRED", "SAFE / ON TRACK")))
A38: Fuji | C38: Ravico | D38: DPIPT | E38: PT DAYA PIONEER INTERNATIONAL | F38: M | G38: 7.26.00626 | H38: Leads | I38: 0 | J38: 59 | K38: Reach Truck 1.5 Ton (1 Unit) _ 1 Tahun _ Canvassing awal & Sales Call | L38: =IF(AND(H38="Leads", J38<=0), "OVERDUE (IDLE)", IF(AND(H38="Leads", J38<=14), "WARNING (3-14 Days)", IF(AND(H38="Prospect", J38<=0), "PROSPECT EXPIRED", "SAFE / ON TRACK")))
A39: Fuji | C39: Ravico | D39: MAXISNACKS | E39: MAXINDO KARYA ANUGERAH | F39: S | G39: 7.26.00633 | H39: Leads | I39: 0 | J39: 60 | K39: Reach Truck 1.5 Ton (1 Unit) _ 1 Tahun _ Canvassing awal & Sales Call | L39: =IF(AND(H39="Leads", J39<=0), "OVERDUE (IDLE)", IF(AND(H39="Leads", J39<=14), "WARNING (3-14 Days)", IF(AND(H39="Prospect", J39<=0), "PROSPECT EXPIRED", "SAFE / ON TRACK")))
A40: Fuji | C40: Ravico | D40: GMN | E40: PT GESITS MOTOR NUSANTARA | F40: M | G40: 7.26.00636 | H40: Leads | I40: 0 | J40: 60 | K40: Reach Truck 1.5 Ton (1 Unit) _ 1 Tahun _ Canvassing awal & Sales Call | L40: =IF(AND(H40="Leads", J40<=0), "OVERDUE (IDLE)", IF(AND(H40="Leads", J40<=14), "WARNING (3-14 Days)", IF(AND(H40="Prospect", J40<=0), "PROSPECT EXPIRED", "SAFE / ON TRACK")))
